Workbook

Sheet Cover
A1: Solar Deal Desk - 100 MWp Thar Sun Energy deal model
A2: Portfolio project | fictional customer & supplier | all monetary values in INR unless stated
A4: Purpose | B4: One connected deal: customer brief -> energy assumptions -> quote -> margin check -> customer value -> project finance (stretch).
A5: Supplier (fictional) | B5: SunAxis Trackers Pvt Ltd - single-axis tracker supplier (not a real company).
A6: Customer (fictional) | B6: Thar Sun Energy Pvt Ltd - IPP developing a 100 MWp (DC) plant, Jodhpur district, Rajasthan.
A8: SHEET GUIDE
A9: Assumptions | B9: Single source of truth. Every number used anywhere in the project lives here (and is re-used in the quotation, deck and README).
A10: Energy | B10: PVGIS v5.3 simulated yield: fixed-tilt (optimal) vs horizontal single-axis tracking, plus a planning-case realisation haircut.
A11: Quote_Calculator | B11: Cost build-up, net price, contribution margin, minimum acceptable price, discount authority, competitor gap.
A12: Sensitivity | B12: Contribution margin vs FX (INR/USD) and steel price; CM vs discount.
A13: Tracker_Value | B13: Customer view: does extra tracker energy value offset extra cost? NPV, IRR, payback, break-even tracker price.
A14: Project_Finance | B14: STRETCH: 25-year project cash flows - project IRR, equity IRR, DSCR, LCOE (pre-tax, simplified).
A15: Deal_Summary | B15: One-page output panel used for the proposal pack and management presentation.
A17: COLOUR LEGEND
A18: Blue text | B18: Hard-coded input - edit these (on Assumptions sheet only).
A19: Yellow fill | B19: Key assumption / scenario lever.
A20: Black text | B20: Formula.
A21: Green text | B21: Link pulled from another sheet.
A22: Green fill | B22: Key output.
A24: DATA LABELS
A25: PVGIS simulated | B25: Output of the EU JRC PVGIS model for a fictional site. A simulated scenario - NOT proof of any manufacturer's real-world tracker performance.
A26: Market benchmark | B26: Public data point used as a planning reference (source cited).
A27: Synthetic assumption | B27: Made-up but realistic value chosen for this portfolio exercise. Replace with real data when available.
A28: Customer brief | B28: Comes from the fictional Customer Requirements Brief.

Sheet Deal_Summary
A1: Deal summary - Thar Sun Energy 100 MWp | SunAxis single-axis tracker
A2: All values link to model sheets. Energy = PVGIS SIMULATED planning case; costs = SYNTHETIC assumptions.
A4: Metric | B4: Value | C4: Unit
A5: COMMERCIAL
A6: Plant size | B6: =Assumptions!$C$6 -> 100 | C6: MWp
A7: List price | B7: =Quote_Calculator!D20 -> 8.1 | C7: INR/Wp
A8: Discount | B8: =Quote_Calculator!D21 -> 0.03 | C8: %
A9: Net price | B9: =Quote_Calculator!D22 -> 7.857 | C9: INR/Wp
A10: Contract value | B10: =Quote_Calculator!E22 -> 78.57 | C10: INR crore
A11: Contract value (USD) | B11: =Quote_Calculator!E22*10^7/Assumptions!$C$19/10^6 -> 8.2748815 | C11: USD million
A12: Contribution margin | B12: =Quote_Calculator!E26 -> 12.26225 | C12: INR crore
A13: Contribution margin % | B13: =Quote_Calculator!D27 -> 0.15606784 | C13: %
A14: Minimum acceptable price | B14: =Quote_Calculator!D32 -> 7.5255556 | C14: INR/Wp
A15: Max discount before CM floor | B15: =Quote_Calculator!D34 -> 0.070919067 | C15: %
A16: Margin status | B16: =Quote_Calculator!D35 -> OK - below target
A17: Approval required | B17: =Quote_Calculator!D36 -> Sales Manager
A18: Competitor offer | B18: =Quote_Calculator!D38 -> 7.6 | C18: INR/Wp
A19: CM % if matching competitor | B19: =Quote_Calculator!D41 -> 0.128375 | C19: %
A20: CUSTOMER VALUE
A21: Simulated tracker gain (ideal PVGIS) | B21: =Energy!B22 -> 0.24280252 | C21: %
A22: Planning-case tracker gain | B22: =Energy!B23 -> 0.16996177 | C22: %
A23: Incremental energy, year 1 | B23: =Energy!B26 -> 29.6947 | C23: GWh
A24: NPV of tracker upgrade | B24: =Tracker_Value!K5 -> 26.813178 | C24: INR crore
A25: IRR of tracker upgrade | B25: =Tracker_Value!K6 -> 0.17331375 | C25: %
A26: Payback of tracker upgrade | B26: =Tracker_Value!K7 -> 5.5174856 | C26: years
A27: Break-even tracker price | B27: =Tracker_Value!K9 -> 10.538318 | C27: INR/Wp
A28: Extra yield to justify premium vs competitor | B28: =Tracker_Value!K15 -> 0.0059872706 | C28: % of fixed yield
A29: PROJECT FINANCE (STRETCH)
A30: Project IRR - fixed / tracker | B30: =TEXT(Project_Finance!B45,"0.0%")&" / "&TEXT(Project_Finance!C45,"0.0%") -> 10.1% / 10.8%
A31: Equity IRR - fixed / tracker | B31: =TEXT(Project_Finance!B46,"0.0%")&" / "&TEXT(Project_Finance!C46,"0.0%") -> 11.2% / 13.2%
A32: Min DSCR - fixed / tracker | B32: =TEXT(Project_Finance!B48,"0.00")&"x / "&TEXT(Project_Finance!C48,"0.00")&"x" -> 1.10x / 1.16x
A33: LCOE - fixed / tracker | B33: =TEXT(Project_Finance!B50,"0.000")&" / "&TEXT(Project_Finance!C50,"0.000") -> 2.426 / 2.312 | C33: INR/kWh

Sheet Assumptions
A1: Assumptions register - single source of truth
A2: Change inputs ONLY here. Type column distinguishes simulated / benchmark / synthetic data.
A4: ID | B4: Parameter | C4: Value | D4: Unit | E4: Type | F4: Source / note
A5: 1. Project (customer brief)
A6: proj_mwp | B6: Plant DC capacity | C6: 100 | D6: MWp | E6: Customer brief | F6: Customer Requirements Brief s.2. Tracker is quoted per Wp DC.
A7: site_lat | B7: Site latitude | C7: 27.3 | D7: deg N | E7: Customer brief | F7: Fictional site, Jodhpur district, Rajasthan.
A8: site_lon | B8: Site longitude | C8: 72.4 | D8: deg E | E8: Customer brief | F8: Fictional site.
A9: life | B9: Project life | C9: 25 | D9: years | E9: Synthetic assumption | F9: Typical PPA tenor in Indian solar auctions.
A11: 2. Energy (simulated)
A12: e_fixed | B12: Fixed-tilt specific yield (30 deg, optimal) | C12: 1747.14 | D12: kWh/kWp/yr | E12: PVGIS simulated | F12: PVGIS v5.3 PVcalc, PVGIS-ERA5 2005-2023, 14% system loss, optimal slope 30 deg / azimuth -6 deg. Run 24-Oct-2026.
A13: e_sat | B13: Single-axis tracker yield (horizontal N-S, ideal) | C13: 2171.35 | D13: kWh/kWp/yr | E13: PVGIS simulated | F13: PVGIS v5.3 PVcalc inclined_axis=1, axis slope 0 deg. PVGIS models ideal rotation: no backtracking, row-to-row shading or stow losses.
A14: realise | B14: Share of simulated tracker gain realised (planning case) | C14: 0.7 | D14: % | E14: Synthetic assumption | F14: Haircut for effects PVGIS does not model. 70% of the 24.3% simulated gain = ~17%, inside the 15-25% range often cited for single-axis trackers (Antai Solar lifecycle-cost blog).
A15: degr | B15: Annual module degradation | C15: 0.005 | D15: %/yr | E15: Synthetic assumption | F15: Typical c-Si warranty degradation.
A17: 3. Market & finance
A18: tariff | B18: PPA tariff | C18: 2.6 | D18: INR/kWh | E18: Market benchmark | F18: Indian ISTS solar auctions have cleared ~INR 2.55-2.68/kWh (PV Tech 2019: 2.55-2.61; Mercom, May-2024 NTPC: 2.68).
A19: fx | B19: Exchange rate | C19: 94.95 | D19: INR per USD | E19: Market benchmark | F19: USD/INR close 23-Oct-2026 (poundsterlinglive.com history).
A20: capex_base | B20: Plant capex excluding mounting structure | C20: 31 | D20: INR/Wp | E20: Synthetic assumption | F20: Set so fixed-tilt total = INR 3.5 cr/MW, the CTUIL planning benchmark (GreentechLead, Sep-2026). Real project costs run higher (INR 4.15-5.49 cr/MW).
A21: fixed_struct | B21: Fixed-tilt structure price (alternative) | C21: 4 | D21: INR/Wp | E21: Synthetic assumption | F21: Customer's fixed-tilt alternative quote from brief.
A22: om_fixed | B22: O&M cost - fixed-tilt plant | C22: 4 | D22: INR lakh/MWp/yr | E22: Synthetic assumption | F22: Planning value.
A23: om_trk_extra | B23: Additional O&M for tracker | C23: 0.6 | D23: INR lakh/MWp/yr | E23: Synthetic assumption | F23: ~15% uplift; source range 15-30% higher than fixed-tilt (Antai Solar).
A24: om_esc | B24: O&M escalation | C24: 0.03 | D24: %/yr | E24: Synthetic assumption
A25: wacc | B25: Customer discount rate (WACC) | C25: 0.09 | D25: % | E25: Synthetic assumption | F25: Used for NPV of incremental tracker value.
A26: gearing | B26: Debt share of capex (stretch) | C26: 0.75 | D26: % | E26: Synthetic assumption | F26: Project finance sheet only.
A27: debt_rate | B27: Debt interest rate (stretch) | C27: 0.0925 | D27: % | E27: Synthetic assumption
A28: tenor | B28: Debt tenor (stretch) | C28: 15 | D28: years | E28: Synthetic assumption | F28: Annuity repayment.
A30: 4. Supplier cost build-up (tracker)
A31: c_steel | B31: Torque tubes & structural steel | C31: 3.6 | D31: INR/Wp | E31: Synthetic assumption | F31: Domestic steel, INR-denominated, steel-index exposed.
A32: c_piles | B32: Piles / foundation steel | C32: 0.9 | D32: INR/Wp | E32: Synthetic assumption | F32: Steel-index exposed.
A33: c_drives | B33: Drives, motors, gearboxes (imported) | C33: 0.008 | D33: USD/Wp | E33: Synthetic assumption | F33: USD-denominated -> FX exposed.
A34: c_ctrl | B34: Controllers, sensors, network (imported) | C34: 0.005 | D34: USD/Wp | E34: Synthetic assumption | F34: USD-denominated -> FX exposed.
A35: c_fast | B35: Fasteners & module clamps | C35: 0.25 | D35: INR/Wp | E35: Synthetic assumption
A36: c_log | B36: Logistics (inland freight, handling) | C36: 0.3 | D36: INR/Wp | E36: Synthetic assumption | F36: Plant to Jodhpur site.
A37: c_inst | B37: Installation supervision & commissioning | C37: 0.15 | D37: INR/Wp | E37: Synthetic assumption
A38: warranty | B38: Warranty reserve | C38: 0.015 | D38: % of net price | E38: Synthetic assumption
A39: commission | B39: Sales commission | C39: 0.01 | D39: % of net price | E39: Synthetic assumption
A41: 5. Pricing policy
A42: list_price | B42: List price | C42: 8.1 | D42: INR/Wp | E42: Synthetic assumption | F42: SunAxis price book, India utility-scale.
A43: discount | B43: Proposed discount | C43: 0.03 | D43: % | E43: Synthetic assumption | F43: Scenario lever - deal desk recommendation.
A44: cm_floor | B44: Minimum contribution margin | C44: 0.12 | D44: % | E44: Synthetic assumption | F44: Below this the deal must not be signed without CFO review.
A45: cm_target | B45: Target contribution margin | C45: 0.18 | D45: % | E45: Synthetic assumption
...

Sheet Energy
A1: Energy comparison - PVGIS SIMULATED scenarios (not measured performance)
A2: Fictional site 27.30N 72.40E | per 1 kWp | monthly values pasted from PVGIS v5.3 API output (24-Oct-2026)
A4: Month | B4: Fixed-tilt (PVGIS) kWh/kWp | C4: Tracker ideal (PVGIS) kWh/kWp | D4: Tracker planning case kWh/kWp | E4: Planning gain %
A5: Jan | B5: 160.08 | C5: 166.3 | D5: =B5+(C5-B5)*Assumptions!$C$14 -> 164.434 | E5: =IFERROR(D5/B5-1,0) -> 0.027198901
A6: Feb | B6: 150.92 | C6: 172.36 | D6: =B6+(C6-B6)*Assumptions!$C$14 -> 165.928 | E6: =IFERROR(D6/B6-1,0) -> 0.099443414
A7: Mar | B7: 164.47 | C7: 205.78 | D7: =B7+(C7-B7)*Assumptions!$C$14 -> 193.387 | E7: =IFERROR(D7/B7-1,0) -> 0.1758193
A8: Apr | B8: 155.5 | C8: 215.76 | D8: =B8+(C8-B8)*Assumptions!$C$14 -> 197.682 | E8: =IFERROR(D8/B8-1,0) -> 0.27126688
A9: May | B9: 150.07 | C9: 226.17 | D9: =B9+(C9-B9)*Assumptions!$C$14 -> 203.34 | E9: =IFERROR(D9/B9-1,0) -> 0.35496768
A10: Jun | B10: 132.36 | C10: 198.64 | D10: =B10+(C10-B10)*Assumptions!$C$14 -> 178.756 | E10: =IFERROR(D10/B10-1,0) -> 0.35052886
A11: Jul | B11: 120.53 | C11: 168.1 | D11: =B11+(C11-B11)*Assumptions!$C$14 -> 153.829 | E11: =IFERROR(D11/B11-1,0) -> 0.27627147
A12: Aug | B12: 119.66 | C12: 155.82 | D12: =B12+(C12-B12)*Assumptions!$C$14 -> 144.972 | E12: =IFERROR(D12/B12-1,0) -> 0.21153268
A13: Sep | B13: 133.21 | C13: 167.78 | D13: =B13+(C13-B13)*Assumptions!$C$14 -> 157.409 | E13: =IFERROR(D13/B13-1,0) -> 0.18166054
A14: Oct | B14: 155.36 | C14: 181.77 | D14: =B14+(C14-B14)*Assumptions!$C$14 -> 173.847 | E14: =IFERROR(D14/B14-1,0) -> 0.11899459
A15: Nov | B15: 148.4 | C15: 155.39 | D15: =B15+(C15-B15)*Assumptions!$C$14 -> 153.293 | E15: =IFERROR(D15/B15-1,0) -> 0.032971698
A16: Dec | B16: 156.59 | C16: 157.47 | D16: =B16+(C16-B16)*Assumptions!$C$14 -> 157.206 | E16: =IFERROR(D16/B16-1,0) -> 0.00393384
A17: Annual total | B17: =SUM(B5:B16) -> 1747.15 | C17: =SUM(C5:C16) -> 2171.34 | D17: =SUM(D5:D16) -> 2044.083 | E17: =IFERROR(D17/B17-1,0) -> 0.16995278
A19: Check vs PVGIS annual totals (should be ~0 rounding) | B19: =B17-Assumptions!$C$12 -> 0.01 | C19: =C17-Assumptions!$C$13 -> -0.01
A21: Key energy outputs
A22: Simulated tracker gain (ideal) | B22: =Assumptions!$C$13/Assumptions!$C$12-1 -> 0.24280252
A23: Planning-case tracker gain | B23: =Assumptions!$C$14*(Assumptions!$C$13/Assumptions!$C$12-1) -> 0.16996177
A24: Fixed-tilt yield, year 1 (GWh) | B24: =Assumptions!$C$12*Assumptions!$C$6/1000 -> 174.714
A25: Tracker planning yield, year 1 (GWh) | B25: =(Assumptions!$C$12+(Assumptions!$C$13-Assumptions!$C$12)*Assumptions!$C$14)*Assumptions!$C$6/1000 -> 204.4087
A26: Incremental energy, year 1 (GWh) | B26: =B25-B24 -> 29.6947
A27: Fixed-tilt capacity factor (DC) | B27: =Assumptions!$C$12/8760 -> 0.19944521
A28: Tracker planning capacity factor (DC) | B28: =B25*1000/Assumptions!$C$6/8760 -> 0.23334326
A30: Labelling rule: these are SIMULATED scenarios from a general-purpose solar model for a fictional site.
A31: PVGIS single-axis option assumes ideal rotation; it does not model backtracking, row-to-row shading, wind stow or tracker availability.
A32: Therefore the planning case applies a realisation factor (Assumptions: realise). A bankable study would use PVsyst/SAM with real layout, GCR and module data.
A33: Reproduce: https://re.jrc.ec.europa.eu/api/v5_3/PVcalc?lat=27.30&lon=72.40&peakpower=1&loss=14&mountingplace=free&optimalangles=1&outputformat=json
A34: and ...&inclined_axis=1&inclinedaxisangle=0 for the tracker run.

Sheet Quote_Calculator
A1: Quote & contribution-margin calculator - SunAxis tracker for Thar Sun 100 MWp
A2: INR/Wp unless stated | INR crore totals = INR/Wp x MWp / 10
A4: Project size (MWp) | B4: =Assumptions!$C$6 -> 100
A5: FX (INR/USD) | B5: =Assumptions!$C$19 -> 94.95
A7: Cost line | B7: Currency | C7: Unit cost (local) | D7: INR/Wp | E7: INR crore (deal) | F7: Exposure
A8: Torque tubes & structural steel | B8: INR | C8: =Assumptions!$C$31 -> 3.6 | D8: =C8 -> 3.6 | E8: =D8*$B$4/10 -> 36 | F8: Steel
A9: Piles / foundation steel | B9: INR | C9: =Assumptions!$C$32 -> 0.9 | D9: =C9 -> 0.9 | E9: =D9*$B$4/10 -> 9 | F9: Steel
A10: Drives, motors, gearboxes | B10: USD | C10: =Assumptions!$C$33 -> 0.008 | D10: =C10*$B$5 -> 0.7596 | E10: =D10*$B$4/10 -> 7.596 | F10: FX
A11: Controllers, sensors, network | B11: USD | C11: =Assumptions!$C$34 -> 0.005 | D11: =C11*$B$5 -> 0.47475 | E11: =D11*$B$4/10 -> 4.7475 | F11: FX
A12: Fasteners & module clamps | B12: INR | C12: =Assumptions!$C$35 -> 0.25 | D12: =C12 -> 0.25 | E12: =D12*$B$4/10 -> 2.5 | F12: -
A13: Logistics (inland freight) | B13: INR | C13: =Assumptions!$C$36 -> 0.3 | D13: =C13 -> 0.3 | E13: =D13*$B$4/10 -> 3 | F13: -
A14: Installation supervision & commissioning | B14: INR | C14: =Assumptions!$C$37 -> 0.15 | D14: =C14 -> 0.15 | E14: =D14*$B$4/10 -> 1.5 | F14: -
A15: Total direct cost | D15: =SUM(D8:D14) -> 6.43435 | E15: =SUM(E8:E14) -> 64.3435
A16: of which USD-linked (FX exposed) | D16: =SUMIFS(D8:D14,B8:B14,"USD") -> 1.23435
A17: of which steel-index exposed | D17: =SUMIFS(D8:D14,F8:F14,"Steel") -> 4.5
A19: Pricing & margin | D19: INR/Wp | E19: INR crore (deal) | F19: Note
A20: List price | D20: =Assumptions!$C$42 -> 8.1 | E20: =D20*$B$4/10 -> 81 | F20: Price book
A21: Proposed discount % | D21: =Assumptions!$C$43 -> 0.03 | F21: Scenario lever (Assumptions)
A22: Net price to customer | D22: =D20*(1-D21) -> 7.857 | E22: =D22*$B$4/10 -> 78.57 | F22: Quoted price
A23: Less: total direct cost | D23: =D15 -> 6.43435 | E23: =D23*$B$4/10 -> 64.3435
A24: Less: warranty reserve | D24: =D22*Assumptions!$C$38 -> 0.117855 | E24: =D24*$B$4/10 -> 1.17855 | F24: % of net price
A25: Less: sales commission | D25: =D22*Assumptions!$C$39 -> 0.07857 | E25: =D25*$B$4/10 -> 0.7857 | F25: % of net price
A26: Contribution margin | D26: =D22-D23-D24-D25 -> 1.226225 | E26: =D26*$B$4/10 -> 12.26225
A27: Contribution margin % | D27: =IFERROR(D26/D22,0) -> 0.15606784
A29: Deal-desk checks | D29: Value | F29: Rule
A30: CM floor | D30: =Assumptions!$C$44 -> 0.12
A31: CM target | D31: =Assumptions!$C$45 -> 0.18
A32: Minimum acceptable price (CM = floor) | D32: =D15/(1-D30-Assumptions!$C$38-Assumptions!$C$39) -> 7.5255556 | F32: Direct cost / (1 - floor - warranty% - commission%)
A33: Price at target CM | D33: =D15/(1-D31-Assumptions!$C$38-Assumptions!$C$39) -> 8.093522
A34: Maximum discount before breaching floor | D34: =MAX(0,1-D32/D20) -> 0.070919067
A35: Margin status | D35: =IF(D27<D30,"BELOW FLOOR - do not sign",IF(D27<D31,"OK - below target","OK - at/above target")) -> OK - below target
A36: Approval required | D36: =IF(D27<D30,"CFO + deal review",IF(D21<=Assumptions!$C$46,"Sales Manager",IF(D21<=Assumptions!$C$47,"Sales Director",IF(D21<=Assumptions!$C$48,"VP Sales","CFO")))) -> Sales Manager | F36: Discount authority matrix in Assumptions s.5
A38: Competitor tracker offer | D38: =Assumptions!$C$49 -> 7.6
A39: Our net price vs competitor (INR/Wp) | D39: =D22-D38 -> 0.257
A40: Our net price vs competitor (%) | D40: =IFERROR(D22/D38-1,0) -> 0.033815789
A41: CM % if we matched competitor price | D41: =IFERROR((D38*(1-Assumptions!$C$38-Assumptions!$C$39)-D15)/D38,0) -> 0.128375
A42: Can we match competitor and stay above floor? | D42: =IF(D41>=D30,"Yes","No - sell value, not price") -> Yes

Sheet Sensitivity
A1: Contribution-margin sensitivity (at proposed net price unless stated)
A2: Each cell recomputes CM% from Quote_Calculator components. Red = below CM floor.
A4: Net price (INR/Wp) | B4: =Quote_Calculator!$D$22 -> 7.857
A5: Non-exposed INR cost (INR/Wp) | B5: =Quote_Calculator!$D$15-Quote_Calculator!$D$16-Quote_Calculator!$D$17 -> 0.7
A6: Steel-exposed cost (INR/Wp) | B6: =Quote_Calculator!$D$17 -> 4.5
A7: USD cost (USD/Wp) | B7: =Assumptions!$C$33+Assumptions!$C$34 -> 0.013
A8: Variable selling cost % (warranty + commission) | B8: =Assumptions!$C$38+Assumptions!$C$39 -> 0.025
A9: CM floor | B9: =Assumptions!$C$44 -> 0.12
A11: Table 1: CM% - rows FX (INR/USD), columns steel price change
B12: Steel -> | C12: =-3*Assumptions!$C$53 -> -0.15 | D12: =-2*Assumptions!$C$53 -> -0.1 | E12: =-1*Assumptions!$C$53 -> -0.05 | F12: =0*Assumptions!$C$53 -> 0 | G12: =1*Assumptions!$C$53 -> 0.05 | H12: =2*Assumptions!$C$53 -> 0.1 | I12: =3*Assumptions!$C$53 -> 0.15
B13: =Assumptions!$C$19+-3*Assumptions!$C$52 -> 87.45 | C13: =IFERROR(($B$4*(1-$B$8)-$B$5-$B$6*(1+C$12)-$B$7*$B13)/$B$4,0) -> 0.25438781 | D13: =IFERROR(($B$4*(1-$B$8)-$B$5-$B$6*(1+D$12)-$B$7*$B13)/$B$4,0) -> 0.22575092 | E13: =IFERROR(($B$4*(1-$B$8)-$B$5-$B$6*(1+E$12)-$B$7*$B13)/$B$4,0) -> 0.19711404 | F13: =IFERROR(($B$4*(1-$B$8)-$B$5-$B$6*(1+F$12)-$B$7*$B13)/$B$4,0) -> 0.16847715 | G13: =IFERROR(($B$4*(1-$B$8)-$B$5-$B$6*(1+G$12)-$B$7*$B13)/$B$4,0) -> 0.13984027 | H13: =IFERROR(($B$4*(1-$B$8)-$B$5-$B$6*(1+H$12)-$B$7*$B13)/$B$4,0) -> 0.11120339 | I13: =IFERROR(($B$4*(1-$B$8)-$B$5-$B$6*(1+I$12)-$B$7*$B13)/$B$4,0) -> 0.082566501
B14: =Assumptions!$C$19+-2*Assumptions!$C$52 -> 89.95 | C14: =IFERROR(($B$4*(1-$B$8)-$B$5-$B$6*(1+C$12)-$B$7*$B14)/$B$4,0) -> 0.25025137 | D14: =IFERROR(($B$4*(1-$B$8)-$B$5-$B$6*(1+D$12)-$B$7*$B14)/$B$4,0) -> 0.22161448 | E14: =IFERROR(($B$4*(1-$B$8)-$B$5-$B$6*(1+E$12)-$B$7*$B14)/$B$4,0) -> 0.1929776 | F14: =IFERROR(($B$4*(1-$B$8)-$B$5-$B$6*(1+F$12)-$B$7*$B14)/$B$4,0) -> 0.16434072 | G14: =IFERROR(($B$4*(1-$B$8)-$B$5-$B$6*(1+G$12)-$B$7*$B14)/$B$4,0) -> 0.13570383 | H14: =IFERROR(($B$4*(1-$B$8)-$B$5-$B$6*(1+H$12)-$B$7*$B14)/$B$4,0) -> 0.10706695 | I14: =IFERROR(($B$4*(1-$B$8)-$B$5-$B$6*(1+I$12)-$B$7*$B14)/$B$4,0) -> 0.078430062
B15: =Assumptions!$C$19+-1*Assumptions!$C$52 -> 92.45 | C15: =IFERROR(($B$4*(1-$B$8)-$B$5-$B$6*(1+C$12)-$B$7*$B15)/$B$4,0) -> 0.24611493 | D15: =IFERROR(($B$4*(1-$B$8)-$B$5-$B$6*(1+D$12)-$B$7*$B15)/$B$4,0) -> 0.21747805 | E15: =IFERROR(($B$4*(1-$B$8)-$B$5-$B$6*(1+E$12)-$B$7*$B15)/$B$4,0) -> 0.18884116 | F15: =IFERROR(($B$4*(1-$B$8)-$B$5-$B$6*(1+F$12)-$B$7*$B15)/$B$4,0) -> 0.16020428 | G15: =IFERROR(($B$4*(1-$B$8)-$B$5-$B$6*(1+G$12)-$B$7*$B15)/$B$4,0) -> 0.13156739 | H15: =IFERROR(($B$4*(1-$B$8)-$B$5-$B$6*(1+H$12)-$B$7*$B15)/$B$4,0) -> 0.10293051 | I15: =IFERROR(($B$4*(1-$B$8)-$B$5-$B$6*(1+I$12)-$B$7*$B15)/$B$4,0) -> 0.074293624
B16: =Assumptions!$C$19+0*Assumptions!$C$52 -> 94.95 | C16: =IFERROR(($B$4*(1-$B$8)-$B$5-$B$6*(1+C$12)-$B$7*$B16)/$B$4,0) -> 0.24197849 | D16: =IFERROR(($B$4*(1-$B$8)-$B$5-$B$6*(1+D$12)-$B$7*$B16)/$B$4,0) -> 0.21334161 | E16: =IFERROR(($B$4*(1-$B$8)-$B$5-$B$6*(1+E$12)-$B$7*$B16)/$B$4,0) -> 0.18470472 | F16: =IFERROR(($B$4*(1-$B$8)-$B$5-$B$6*(1+F$12)-$B$7*$B16)/$B$4,0) -> 0.15606784 | G16: =IFERROR(($B$4*(1-$B$8)-$B$5-$B$6*(1+G$12)-$B$7*$B16)/$B$4,0) -> 0.12743095 | H16: =IFERROR(($B$4*(1-$B$8)-$B$5-$B$6*(1+H$12)-$B$7*$B16)/$B$4,0) -> 0.098794069 | I16: =IFERROR(($B$4*(1-$B$8)-$B$5-$B$6*(1+I$12)-$B$7*$B16)/$B$4,0) -> 0.070157185
B17: =Assumptions!$C$19+1*Assumptions!$C$52 -> 97.45 | C17: =IFERROR(($B$4*(1-$B$8)-$B$5-$B$6*(1+C$12)-$B$7*$B17)/$B$4,0) -> 0.23784205 | D17: =IFERROR(($B$4*(1-$B$8)-$B$5-$B$6*(1+D$12)-$B$7*$B17)/$B$4,0) -> 0.20920517 | E17: =IFERROR(($B$4*(1-$B$8)-$B$5-$B$6*(1+E$12)-$B$7*$B17)/$B$4,0) -> 0.18056828 | F17: =IFERROR(($B$4*(1-$B$8)-$B$5-$B$6*(1+F$12)-$B$7*$B17)/$B$4,0) -> 0.1519314 | G17: =IFERROR(($B$4*(1-$B$8)-$B$5-$B$6*(1+G$12)-$B$7*$B17)/$B$4,0) -> 0.12329451 | H17: =IFERROR(($B$4*(1-$B$8)-$B$5-$B$6*(1+H$12)-$B$7*$B17)/$B$4,0) -> 0.09465763 | I17: =IFERROR(($B$4*(1-$B$8)-$B$5-$B$6*(1+I$12)-$B$7*$B17)/$B$4,0) -> 0.066020746
B18: =Assumptions!$C$19+2*Assumptions!$C$52 -> 99.95 | C18: =IFERROR(($B$4*(1-$B$8)-$B$5-$B$6*(1+C$12)-$B$7*$B18)/$B$4,0) -> 0.23370561 | D18: =IFERROR(($B$4*(1-$B$8)-$B$5-$B$6*(1+D$12)-$B$7*$B18)/$B$4,0) -> 0.20506873 | E18: =IFERROR(($B$4*(1-$B$8)-$B$5-$B$6*(1+E$12)-$B$7*$B18)/$B$4,0) -> 0.17643184 | F18: =IFERROR(($B$4*(1-$B$8)-$B$5-$B$6*(1+F$12)-$B$7*$B18)/$B$4,0) -> 0.14779496 | G18: =IFERROR(($B$4*(1-$B$8)-$B$5-$B$6*(1+G$12)-$B$7*$B18)/$B$4,0) -> 0.11915808 | H18: =IFERROR(($B$4*(1-$B$8)-$B$5-$B$6*(1+H$12)-$B$7*$B18)/$B$4,0) -> 0.090521191 | I18: =IFERROR(($B$4*(1-$B$8)-$B$5-$B$6*(1+I$12)-$B$7*$B18)/$B$4,0) -> 0.061884307
B19: =Assumptions!$C$19+3*Assumptions!$C$52 -> 102.45 | C19: =IFERROR(($B$4*(1-$B$8)-$B$5-$B$6*(1+C$12)-$B$7*$B19)/$B$4,0) -> 0.22956917 | D19: =IFERROR(($B$4*(1-$B$8)-$B$5-$B$6*(1+D$12)-$B$7*$B19)/$B$4,0) -> 0.20093229 | E19: =IFERROR(($B$4*(1-$B$8)-$B$5-$B$6*(1+E$12)-$B$7*$B19)/$B$4,0) -> 0.17229541 | F19: =IFERROR(($B$4*(1-$B$8)-$B$5-$B$6*(1+F$12)-$B$7*$B19)/$B$4,0) -> 0.14365852 | G19: =IFERROR(($B$4*(1-$B$8)-$B$5-$B$6*(1+G$12)-$B$7*$B19)/$B$4,0) -> 0.11502164 | H19: =IFERROR(($B$4*(1-$B$8)-$B$5-$B$6*(1+H$12)-$B$7*$B19)/$B$4,0) -> 0.086384752 | I19: =IFERROR(($B$4*(1-$B$8)-$B$5-$B$6*(1+I$12)-$B$7*$B19)/$B$4,0) -> 0.057747868
B20: =Assumptions!$C$19+4*Assumptions!$C$52 -> 104.95 | C20: =IFERROR(($B$4*(1-$B$8)-$B$5-$B$6*(1+C$12)-$B$7*$B20)/$B$4,0) -> 0.22543274 | D20: =IFERROR(($B$4*(1-$B$8)-$B$5-$B$6*(1+D$12)-$B$7*$B20)/$B$4,0) -> 0.19679585 | E20: =IFERROR(($B$4*(1-$B$8)-$B$5-$B$6*(1+E$12)-$B$7*$B20)/$B$4,0) -> 0.16815897 | F20: =IFERROR(($B$4*(1-$B$8)-$B$5-$B$6*(1+F$12)-$B$7*$B20)/$B$4,0) -> 0.13952208 | G20: =IFERROR(($B$4*(1-$B$8)-$B$5-$B$6*(1+G$12)-$B$7*$B20)/$B$4,0) -> 0.1108852 | H20: =IFERROR(($B$4*(1-$B$8)-$B$5-$B$6*(1+H$12)-$B$7*$B20)/$B$4,0) -> 0.082248314 | I20: =IFERROR(($B$4*(1-$B$8)-$B$5-$B$6*(1+I$12)-$B$7*$B20)/$B$4,0) -> 0.053611429
A23: Table 2: CM% - rows discount, columns FX (steel at base)
B24: FX -> | C24: =Assumptions!$C$19+-2*Assumptions!$C$52 -> 89.95 | D24: =Assumptions!$C$19+-1*Assumptions!$C$52 -> 92.45 | E24: =Assumptions!$C$19+0*Assumptions!$C$52 -> 94.95 | F24: =Assumptions!$C$19+1*Assumptions!$C$52 -> 97.45 | G24: =Assumptions!$C$19+2*Assumptions!$C$52 -> 99.95 | H24: =Assumptions!$C$19+3*Assumptions!$C$52 -> 102.45
B25: 0 | C25: =IFERROR((Assumptions!$C$42*(1-$B25)*(1-$B$8)-$B$5-$B$6-$B$7*C$24)/(Assumptions!$C$42*(1-$B25)),0) -> 0.18866049 | D25: =IFERROR((Assumptions!$C$42*(1-$B25)*(1-$B$8)-$B$5-$B$6-$B$7*D$24)/(Assumptions!$C$42*(1-$B25)),0) -> 0.18464815 | E25: =IFERROR((Assumptions!$C$42*(1-$B25)*(1-$B$8)-$B$5-$B$6-$B$7*E$24)/(Assumptions!$C$42*(1-$B25)),0) -> 0.1806358 | F25: =IFERROR((Assumptions!$C$42*(1-$B25)*(1-$B$8)-$B$5-$B$6-$B$7*F$24)/(Assumptions!$C$42*(1-$B25)),0) -> 0.17662346 | G25: =IFERROR((Assumptions!$C$42*(1-$B25)*(1-$B$8)-$B$5-$B$6-$B$7*G$24)/(Assumptions!$C$42*(1-$B25)),0) -> 0.17261111 | H25: =IFERROR((Assumptions!$C$42*(1-$B25)*(1-$B$8)-$B$5-$B$6-$B$7*H$24)/(Assumptions!$C$42*(1-$B25)),0) -> 0.16859877
B26: 0.02 | C26: =IFERROR((Assumptions!$C$42*(1-$B26)*(1-$B$8)-$B$5-$B$6-$B$7*C$24)/(Assumptions!$C$42*(1-$B26)),0) -> 0.17261275 | D26: =IFERROR((Assumptions!$C$42*(1-$B26)*(1-$B$8)-$B$5-$B$6-$B$7*D$24)/(Assumptions!$C$42*(1-$B26)),0) -> 0.16851852 | E26: =IFERROR((Assumptions!$C$42*(1-$B26)*(1-$B$8)-$B$5-$B$6-$B$7*E$24)/(Assumptions!$C$42*(1-$B26)),0) -> 0.16442429 | F26: =IFERROR((Assumptions!$C$42*(1-$B26)*(1-$B$8)-$B$5-$B$6-$B$7*F$24)/(Assumptions!$C$42*(1-$B26)),0) -> 0.16033006 | G26: =IFERROR((Assumptions!$C$42*(1-$B26)*(1-$B$8)-$B$5-$B$6-$B$7*G$24)/(Assumptions!$C$42*(1-$B26)),0) -> 0.15623583 | H26: =IFERROR((Assumptions!$C$42*(1-$B26)*(1-$B$8)-$B$5-$B$6-$B$7*H$24)/(Assumptions!$C$42*(1-$B26)),0) -> 0.1521416
B27: 0.03 | C27: =IFERROR((Assumptions!$C$42*(1-$B27)*(1-$B$8)-$B$5-$B$6-$B$7*C$24)/(Assumptions!$C$42*(1-$B27)),0) -> 0.16434072 | D27: =IFERROR((Assumptions!$C$42*(1-$B27)*(1-$B$8)-$B$5-$B$6-$B$7*D$24)/(Assumptions!$C$42*(1-$B27)),0) -> 0.16020428 | E27: =IFERROR((Assumptions!$C$42*(1-$B27)*(1-$B$8)-$B$5-$B$6-$B$7*E$24)/(Assumptions!$C$42*(1-$B27)),0) -> 0.15606784 | F27: =IFERROR((Assumptions!$C$42*(1-$B27)*(1-$B$8)-$B$5-$B$6-$B$7*F$24)/(Assumptions!$C$42*(1-$B27)),0) -> 0.1519314 | G27: =IFERROR((Assumptions!$C$42*(1-$B27)*(1-$B$8)-$B$5-$B$6-$B$7*G$24)/(Assumptions!$C$42*(1-$B27)),0) -> 0.14779496 | H27: =IFERROR((Assumptions!$C$42*(1-$B27)*(1-$B$8)-$B$5-$B$6-$B$7*H$24)/(Assumptions!$C$42*(1-$B27)),0) -> 0.14365852
B28: 0.04 | C28: =IFERROR((Assumptions!$C$42*(1-$B28)*(1-$B$8)-$B$5-$B$6-$B$7*C$24)/(Assumptions!$C$42*(1-$B28)),0) -> 0.15589635 | D28: =IFERROR((Assumptions!$C$42*(1-$B28)*(1-$B$8)-$B$5-$B$6-$B$7*D$24)/(Assumptions!$C$42*(1-$B28)),0) -> 0.15171682 | E28: =IFERROR((Assumptions!$C$42*(1-$B28)*(1-$B$8)-$B$5-$B$6-$B$7*E$24)/(Assumptions!$C$42*(1-$B28)),0) -> 0.14753729 | F28: =IFERROR((Assumptions!$C$42*(1-$B28)*(1-$B$8)-$B$5-$B$6-$B$7*F$24)/(Assumptions!$C$42*(1-$B28)),0) -> 0.14335777 | G28: =IFERROR((Assumptions!$C$42*(1-$B28)*(1-$B$8)-$B$5-$B$6-$B$7*G$24)/(Assumptions!$C$42*(1-$B28)),0) -> 0.13917824 | H28: =IFERROR((Assumptions!$C$42*(1-$B28)*(1-$B$8)-$B$5-$B$6-$B$7*H$24)/(Assumptions!$C$42*(1-$B28)),0) -> 0.13499871
B29: 0.05 | C29: =IFERROR((Assumptions!$C$42*(1-$B29)*(1-$B$8)-$B$5-$B$6-$B$7*C$24)/(Assumptions!$C$42*(1-$B29)),0) -> 0.1472742 | D29: =IFERROR((Assumptions!$C$42*(1-$B29)*(1-$B$8)-$B$5-$B$6-$B$7*D$24)/(Assumptions!$C$42*(1-$B29)),0) -> 0.14305068 | E29: =IFERROR((Assumptions!$C$42*(1-$B29)*(1-$B$8)-$B$5-$B$6-$B$7*E$24)/(Assumptions!$C$42*(1-$B29)),0) -> 0.13882716 | F29: =IFERROR((Assumptions!$C$42*(1-$B29)*(1-$B$8)-$B$5-$B$6-$B$7*F$24)/(Assumptions!$C$42*(1-$B29)),0) -> 0.13460364 | G29: =IFERROR((Assumptions!$C$42*(1-$B29)*(1-$B$8)-$B$5-$B$6-$B$7*G$24)/(Assumptions!$C$42*(1-$B29)),0) -> 0.13038012 | H29: =IFERROR((Assumptions!$C$42*(1-$B29)*(1-$B$8)-$B$5-$B$6-$B$7*H$24)/(Assumptions!$C$42*(1-$B29)),0) -> 0.1261566
B30: 0.06 | C30: =IFERROR((Assumptions!$C$42*(1-$B30)*(1-$B$8)-$B$5-$B$6-$B$7*C$24)/(Assumptions!$C$42*(1-$B30)),0) -> 0.13846861 | D30: =IFERROR((Assumptions!$C$42*(1-$B30)*(1-$B$8)-$B$5-$B$6-$B$7*D$24)/(Assumptions!$C$42*(1-$B30)),0) -> 0.13420016 | E30: =IFERROR((Assumptions!$C$42*(1-$B30)*(1-$B$8)-$B$5-$B$6-$B$7*E$24)/(Assumptions!$C$42*(1-$B30)),0) -> 0.1299317 | F30: =IFERROR((Assumptions!$C$42*(1-$B30)*(1-$B$8)-$B$5-$B$6-$B$7*F$24)/(Assumptions!$C$42*(1-$B30)),0) -> 0.12566325 | G30: =IFERROR((Assumptions!$C$42*(1-$B30)*(1-$B$8)-$B$5-$B$6-$B$7*G$24)/(Assumptions!$C$42*(1-$B30)),0) -> 0.1213948 | H30: =IFERROR((Assumptions!$C$42*(1-$B30)*(1-$B$8)-$B$5-$B$6-$B$7*H$24)/(Assumptions!$C$42*(1-$B30)),0) -> 0.11712635
B31: 0.08 | C31: =IFERROR((Assumptions!$C$42*(1-$B31)*(1-$B$8)-$B$5-$B$6-$B$7*C$24)/(Assumptions!$C$42*(1-$B31)),0) -> 0.12028315 | D31: =IFERROR((Assumptions!$C$42*(1-$B31)*(1-$B$8)-$B$5-$B$6-$B$7*D$24)/(Assumptions!$C$42*(1-$B31)),0) -> 0.1159219 | E31: =IFERROR((Assumptions!$C$42*(1-$B31)*(1-$B$8)-$B$5-$B$6-$B$7*E$24)/(Assumptions!$C$42*(1-$B31)),0) -> 0.11156065 | F31: =IFERROR((Assumptions!$C$42*(1-$B31)*(1-$B$8)-$B$5-$B$6-$B$7*F$24)/(Assumptions!$C$42*(1-$B31)),0) -> 0.10719941 | G31: =IFERROR((Assumptions!$C$42*(1-$B31)*(1-$B$8)-$B$5-$B$6-$B$7*G$24)/(Assumptions!$C$42*(1-$B31)),0) -> 0.10283816 | H31: =IFERROR((Assumptions!$C$42*(1-$B31)*(1-$B$8)-$B$5-$B$6-$B$7*H$24)/(Assumptions!$C$42*(1-$B31)),0) -> 0.098476919
B32: 0.1 | C32: =IFERROR((Assumptions!$C$42*(1-$B32)*(1-$B$8)-$B$5-$B$6-$B$7*C$24)/(Assumptions!$C$42*(1-$B32)),0) -> 0.10128944 | D32: =IFERROR((Assumptions!$C$42*(1-$B32)*(1-$B$8)-$B$5-$B$6-$B$7*D$24)/(Assumptions!$C$42*(1-$B32)),0) -> 0.096831276 | E32: =IFERROR((Assumptions!$C$42*(1-$B32)*(1-$B$8)-$B$5-$B$6-$B$7*E$24)/(Assumptions!$C$42*(1-$B32)),0) -> 0.092373114 | F32: =IFERROR((Assumptions!$C$42*(1-$B32)*(1-$B$8)-$B$5-$B$6-$B$7*F$24)/(Assumptions!$C$42*(1-$B32)),0) -> 0.087914952 | G32: =IFERROR((Assumptions!$C$42*(1-$B32)*(1-$B$8)-$B$5-$B$6-$B$7*G$24)/(Assumptions!$C$42*(1-$B32)),0) -> 0.08345679 | H32: =IFERROR((Assumptions!$C$42*(1-$B32)*(1-$B$8)-$B$5-$B$6-$B$7*H$24)/(Assumptions!$C$42*(1-$B32)),0) -> 0.078998628
A35: Minimum acceptable price (INR/Wp) by FX | C35: =(Quote_Calculator!$D$15-Quote_Calculator!$D$16+$B$7*C$24)/(1-$B$9-$B$8) -> 7.4495322 | D35: =(Quote_Calculator!$D$15-Quote_Calculator!$D$16+$B$7*D$24)/(1-$B$9-$B$8) -> 7.4875439 | E35: =(Quote_Calculator!$D$15-Quote_Calculator!$D$16+$B$7*E$24)/(1-$B$9-$B$8) -> 7.5255556 | F35: =(Quote_Calculator!$D$15-Quote_Calculator!$D$16+$B$7*F$24)/(1-$B$9-$B$8) -> 7.5635673 | G35: =(Quote_Calculator!$D$15-Quote_Calculator!$D$16+$B$7*G$24)/(1-$B$9-$B$8) -> 7.6015789 | H35: =(Quote_Calculator!$D$15-Quote_Calculator!$D$16+$B$7*H$24)/(1-$B$9-$B$8) -> 7.6395906
A36: Read-across: a 1 INR move in USD/INR changes direct cost by USD cost x 1 = small; steel is the bigger lever for this mostly-domestic BOM.

Sheet Tracker_Value
A1: Customer value case - does extra tracker energy pay for the extra cost?
A2: Incremental cash flows: tracker plant minus fixed-tilt plant | INR crore | pre-tax | uses PVGIS planning case
A4: Tracker net price (INR/Wp) | B4: =Quote_Calculator!$D$22 -> 7.857 | J4: OUTPUTS
A5: Fixed-tilt structure price (INR/Wp) | B5: =Assumptions!$C$21 -> 4 | J5: NPV of tracker upgrade (INR crore) | K5: =G13+NPV(B10,G14:G38) -> 26.813178
A6: Incremental capex (INR crore) | B6: =(B4-B5)*Assumptions!$C$6/10 -> 38.57 | J6: IRR of tracker upgrade | K6: =IFERROR(IRR(G13:G38),0) -> 0.17331375
A7: Incremental energy yr1 (GWh) | B7: =Energy!$B$26 -> 29.6947 | J7: Simple payback (years) | K7: =IFERROR(INDEX(A13:A38,MATCH(TRUE(),INDEX(H13:H38>=0,0),0))-1+(-INDEX(H13:H38,MATCH(TRUE(),INDEX(H13:H38>=0,0),0)-1))/INDEX(G13:G38,MATCH(TRUE(),INDEX(H13:H38>=0,0),0)),"n/a") -> 5.5174856
A8: Tariff (INR/kWh) | B8: =Assumptions!$C$18 -> 2.6 | J8: PV of incremental benefits (INR crore) | K8: =NPV(B10,G14:G38) -> 65.383178
A9: Extra O&M yr1 (INR crore) | B9: =Assumptions!$C$23*Assumptions!$C$6/100 -> 0.6 | J9: Break-even tracker price (INR/Wp, NPV = 0) | K9: =B5+K8/(Assumptions!$C$6/10) -> 10.538318
A10: Discount rate | B10: =Assumptions!$C$25 -> 0.09 | J10: Headroom: break-even minus our net price (INR/Wp) | K10: =K9-B4 -> 2.6813178
J11: Competitor price vs break-even (INR/Wp) | K11: =K9-Assumptions!$C$49 -> 2.9383178
A12: Year | B12: Degradation factor | C12: Incremental energy (GWh) | D12: Incremental revenue (INR cr) | E12: Extra O&M (INR cr) | F12: Incremental capex (INR cr) | G12: Net incremental CF (INR cr) | H12: Cumulative CF (INR cr) | J12: Value of extra energy per Wp (PV, INR/Wp) | K12: =K8/(Assumptions!$C$6/10) -> 6.5383178
A13: 0 | F13: =-B6 -> -38.57 | G13: =F13 -> -38.57 | H13: =G13 -> -38.57 | J13: Our premium over competitor (INR crore) | K13: =(B4-Assumptions!$C$49)*Assumptions!$C$6/10 -> 2.57
A14: 1 | B14: =IF(A14<=Assumptions!$C$9,(1-Assumptions!$C$15)^(A14-1),0) -> 1 | C14: =$B$7*B14 -> 29.6947 | D14: =C14*$B$8/10 -> 7.720622 | E14: =IF(A14<=Assumptions!$C$9,-$B$9*(1+Assumptions!$C$24)^(A14-1),0) -> -0.6 | F14: 0 | G14: =D14+E14+F14 -> 7.120622 | H14: =H13+G14 -> -31.449378 | J14: Extra yr-1 energy that would justify premium (GWh) | K14: =IFERROR(K13/(NPV(B10,D14:D38)/B7),0) -> 1.04606
A15: 2 | B15: =IF(A15<=Assumptions!$C$9,(1-Assumptions!$C$15)^(A15-1),0) -> 0.995 | C15: =$B$7*B15 -> 29.546226 | D15: =C15*$B$8/10 -> 7.6820189 | E15: =IF(A15<=Assumptions!$C$9,-$B$9*(1+Assumptions!$C$24)^(A15-1),0) -> -0.618 | F15: 0 | G15: =D15+E15+F15 -> 7.0640189 | H15: =H14+G15 -> -24.385359 | J15: ...as % of fixed-tilt yield | K15: =IFERROR(K14/Energy!$B$24,0) -> 0.0059872706
A16: 3 | B16: =IF(A16<=Assumptions!$C$9,(1-Assumptions!$C$15)^(A16-1),0) -> 0.990025 | C16: =$B$7*B16 -> 29.398495 | D16: =C16*$B$8/10 -> 7.6436088 | E16: =IF(A16<=Assumptions!$C$9,-$B$9*(1+Assumptions!$C$24)^(A16-1),0) -> -0.63654 | F16: 0 | G16: =D16+E16+F16 -> 7.0070688 | H16: =H15+G16 -> -17.37829
A17: 4 | B17: =IF(A17<=Assumptions!$C$9,(1-Assumptions!$C$15)^(A17-1),0) -> 0.98507488 | C17: =$B$7*B17 -> 29.251503 | D17: =C17*$B$8/10 -> 7.6053908 | E17: =IF(A17<=Assumptions!$C$9,-$B$9*(1+Assumptions!$C$24)^(A17-1),0) -> -0.6556362 | F17: 0 | G17: =D17+E17+F17 -> 6.9497546 | H17: =H16+G17 -> -10.428536 | J17: Interpretation: if our net price is below the break-even price, the tracker creates value for the customer
A18: 5 | B18: =IF(A18<=Assumptions!$C$9,(1-Assumptions!$C$15)^(A18-1),0) -> 0.9801495 | C18: =$B$7*B18 -> 29.105245 | D18: =C18*$B$8/10 -> 7.5673638 | E18: =IF(A18<=Assumptions!$C$9,-$B$9*(1+Assumptions!$C$24)^(A18-1),0) -> -0.67530529 | F18: 0 | G18: =D18+E18+F18 -> 6.8920585 | H18: =H17+G18 -> -3.5364773 | J18: under these SIMULATED energy and SYNTHETIC cost assumptions. Test with realise = 50% on Assumptions.
A19: 6 | B19: =IF(A19<=Assumptions!$C$9,(1-Assumptions!$C$15)^(A19-1),0) -> 0.97524875 | C19: =$B$7*B19 -> 28.959719 | D19: =C19*$B$8/10 -> 7.529527 | E19: =IF(A19<=Assumptions!$C$9,-$B$9*(1+Assumptions!$C$24)^(A19-1),0) -> -0.69556444 | F19: 0 | G19: =D19+E19+F19 -> 6.8339625 | H19: =H18+G19 -> 3.2974853
A20: 7 | B20: =IF(A20<=Assumptions!$C$9,(1-Assumptions!$C$15)^(A20-1),0) -> 0.97037251 | C20: =$B$7*B20 -> 28.814921 | D20: =C20*$B$8/10 -> 7.4918793 | E20: =IF(A20<=Assumptions!$C$9,-$B$9*(1+Assumptions!$C$24)^(A20-1),0) -> -0.71643138 | F20: 0 | G20: =D20+E20+F20 -> 6.775448 | H20: =H19+G20 -> 10.072933
A21: 8 | B21: =IF(A21<=Assumptions!$C$9,(1-Assumptions!$C$15)^(A21-1),0) -> 0.96552065 | C21: =$B$7*B21 -> 28.670846 | D21: =C21*$B$8/10 -> 7.4544199 | E21: =IF(A21<=Assumptions!$C$9,-$B$9*(1+Assumptions!$C$24)^(A21-1),0) -> -0.73792432 | F21: 0 | G21: =D21+E21+F21 -> 6.7164956 | H21: =H20+G21 -> 16.789429
A22: 9 | B22: =IF(A22<=Assumptions!$C$9,(1-Assumptions!$C$15)^(A22-1),0) -> 0.96069304 | C22: =$B$7*B22 -> 28.527492 | D22: =C22*$B$8/10 -> 7.4171478 | E22: =IF(A22<=Assumptions!$C$9,-$B$9*(1+Assumptions!$C$24)^(A22-1),0) -> -0.76006205 | F22: 0 | G22: =D22+E22+F22 -> 6.6570858 | H22: =H21+G22 -> 23.446515
A23: 10 | B23: =IF(A23<=Assumptions!$C$9,(1-Assumptions!$C$15)^(A23-1),0) -> 0.95588958 | C23: =$B$7*B23 -> 28.384854 | D23: =C23*$B$8/10 -> 7.3800621 | E23: =IF(A23<=Assumptions!$C$9,-$B$9*(1+Assumptions!$C$24)^(A23-1),0) -> -0.78286391 | F23: 0 | G23: =D23+E23+F23 -> 6.5971982 | H23: =H22+G23 -> 30.043713
A24: 11 | B24: =IF(A24<=Assumptions!$C$9,(1-Assumptions!$C$15)^(A24-1),0) -> 0.95111013 | C24: =$B$7*B24 -> 28.24293 | D24: =C24*$B$8/10 -> 7.3431618 | E24: =IF(A24<=Assumptions!$C$9,-$B$9*(1+Assumptions!$C$24)^(A24-1),0) -> -0.80634983 | F24: 0 | G24: =D24+E24+F24 -> 6.536812 | H24: =H23+G24 -> 36.580525
A25: 12 | B25: =IF(A25<=Assumptions!$C$9,(1-Assumptions!$C$15)^(A25-1),0) -> 0.94635458 | C25: =$B$7*B25 -> 28.101715 | D25: =C25*$B$8/10 -> 7.306446 | E25: =IF(A25<=Assumptions!$C$9,-$B$9*(1+Assumptions!$C$24)^(A25-1),0) -> -0.83054032 | F25: 0 | G25: =D25+E25+F25 -> 6.4759057 | H25: =H24+G25 -> 43.056431
A26: 13 | B26: =IF(A26<=Assumptions!$C$9,(1-Assumptions!$C$15)^(A26-1),0) -> 0.94162281 | C26: =$B$7*B26 -> 27.961207 | D26: =C26*$B$8/10 -> 7.2699138 | E26: =IF(A26<=Assumptions!$C$9,-$B$9*(1+Assumptions!$C$24)^(A26-1),0) -> -0.85545653 | F26: 0 | G26: =D26+E26+F26 -> 6.4144572 | H26: =H25+G26 -> 49.470888
A27: 14 | B27: =IF(A27<=Assumptions!$C$9,(1-Assumptions!$C$15)^(A27-1),0) -> 0.93691469 | C27: =$B$7*B27 -> 27.821401 | D27: =C27*$B$8/10 -> 7.2335642 | E27: =IF(A27<=Assumptions!$C$9,-$B$9*(1+Assumptions!$C$24)^(A27-1),0) -> -0.88112023 | F27: 0 | G27: =D27+E27+F27 -> 6.352444 | H27: =H26+G27 -> 55.823332
A28: 15 | B28: =IF(A28<=Assumptions!$C$9,(1-Assumptions!$C$15)^(A28-1),0) -> 0.93223012 | C28: =$B$7*B28 -> 27.682294 | D28: =C28*$B$8/10 -> 7.1973964 | E28: =IF(A28<=Assumptions!$C$9,-$B$9*(1+Assumptions!$C$24)^(A28-1),0) -> -0.90755383 | F28: 0 | G28: =D28+E28+F28 -> 6.2898425 | H28: =H27+G28 -> 62.113174
A29: 16 | B29: =IF(A29<=Assumptions!$C$9,(1-Assumptions!$C$15)^(A29-1),0) -> 0.92756897 | C29: =$B$7*B29 -> 27.543882 | D29: =C29*$B$8/10 -> 7.1614094 | E29: =IF(A29<=Assumptions!$C$9,-$B$9*(1+Assumptions!$C$24)^(A29-1),0) -> -0.93478045 | F29: 0 | G29: =D29+E29+F29 -> 6.2266289 | H29: =H28+G29 -> 68.339803
A30: 17 | B30: =IF(A30<=Assumptions!$C$9,(1-Assumptions!$C$15)^(A30-1),0) -> 0.92293112 | C30: =$B$7*B30 -> 27.406163 | D30: =C30*$B$8/10 -> 7.1256023 | E30: =IF(A30<=Assumptions!$C$9,-$B$9*(1+Assumptions!$C$24)^(A30-1),0) -> -0.96282386 | F30: 0 | G30: =D30+E30+F30 -> 6.1627785 | H30: =H29+G30 -> 74.502582
... A38: 25 | B38: =IF(A38<=Assumptions!$C$9,(1-Assumptions!$C$15)^(A38-1),0) -> 0.88665351 | C38: =$B$7*B38 -> 26.32891 | D38: =C38*$B$8/10 -> 6.8455166 | E38: =IF(A38<=Assumptions!$C$9,-$B$9*(1+Assumptions!$C$24)^(A38-1),0) -> -1.2196765 | F38: 0 | G38: =D38+E38+F38 -> 5.6258401 | H38: =H37+G38 -> 121.42104
A39: Total | C39: =SUM(C13:C38) -> 699.48691 | D39: =SUM(D13:D38) -> 181.8666 | E39: =SUM(E13:E38) -> -21.875559 | F39: =SUM(F13:F38) -> -38.57 | G39: =SUM(G13:G38) -> 121.42104

Sheet Project_Finance
A1: STRETCH - project finance view: fixed-tilt vs tracker plant (pre-tax, simplified)
A2: INR crore | annuity debt | no tax, depreciation, working capital or DSRA - extend if time allows
A4: Fixed-tilt capex (INR cr) | B4: =(Assumptions!$C$20+Assumptions!$C$21)*Assumptions!$C$6/10 -> 350
A5: Tracker capex (INR cr) | B5: =(Assumptions!$C$20+Quote_Calculator!$D$22)*Assumptions!$C$6/10 -> 388.57
A6: Fixed yield yr1 (GWh) | B6: =Energy!$B$24 -> 174.714
A7: Tracker yield yr1 (GWh) | B7: =Energy!$B$25 -> 204.4087
A8: O&M fixed yr1 (INR cr) | B8: =Assumptions!$C$22*Assumptions!$C$6/100 -> 4
A9: O&M tracker yr1 (INR cr) | B9: =(Assumptions!$C$22+Assumptions!$C$23)*Assumptions!$C$6/100 -> 4.6
A10: Debt - fixed (INR cr) | B10: =B4*Assumptions!$C$26 -> 262.5
A11: Debt - tracker (INR cr) | B11: =B5*Assumptions!$C$26 -> 291.4275
A12: Annual debt service - fixed | B12: =PMT(Assumptions!$C$27,Assumptions!$C$28,-B10) -> 33.047584
A13: Annual debt service - tracker | B13: =PMT(Assumptions!$C$27,Assumptions!$C$28,-B11) -> 36.689428
A15: Year | B15: Fixed: energy GWh | C15: Fixed: revenue | D15: Fixed: O&M | E15: Fixed: project CF | F15: Fixed: debt service | G15: Fixed: equity CF | H15: Fixed: DSCR | I15: Tracker: energy GWh | J15: Tracker: revenue | K15: Tracker: O&M | L15: Tracker: project CF | M15: Tracker: debt service | N15: Tracker: equity CF | O15: Tracker: DSCR | P15: Discount factor
A16: 0 | E16: =-B4 -> -350 | G16: =-B4*(1-Assumptions!$C$26) -> -87.5 | L16: =-B5 -> -388.57 | N16: =-B5*(1-Assumptions!$C$26) -> -97.1425 | P16: 1
A17: 1 | B17: =$B$6*(1-Assumptions!$C$15)^(A17-1) -> 174.714 | C17: =B17*Assumptions!$C$18/10 -> 45.42564 | D17: =-$B$8*(1+Assumptions!$C$24)^(A17-1) -> -4 | E17: =C17+D17 -> 41.42564 | F17: =IF(A17<=Assumptions!$C$28,-$B$12,0) -> -33.047584 | G17: =E17+F17 -> 8.3780555 | H17: =IF(F17<0,E17/-F17,"") -> 1.2535149 | I17: =$B$7*(1-Assumptions!$C$15)^(A17-1) -> 204.4087 | J17: =I17*Assumptions!$C$18/10 -> 53.146262 | K17: =-$B$9*(1+Assumptions!$C$24)^(A17-1) -> -4.6 | L17: =J17+K17 -> 48.546262 | M17: =IF(A17<=Assumptions!$C$28,-$B$13,0) -> -36.689428 | N17: =L17+M17 -> 11.856834 | O17: =IF(M17<0,L17/-M17,"") -> 1.3231676 | P17: =1/(1+Assumptions!$C$25)^A17 -> 0.91743119
A18: 2 | B18: =$B$6*(1-Assumptions!$C$15)^(A18-1) -> 173.84043 | C18: =B18*Assumptions!$C$18/10 -> 45.198512 | D18: =-$B$8*(1+Assumptions!$C$24)^(A18-1) -> -4.12 | E18: =C18+D18 -> 41.078512 | F18: =IF(A18<=Assumptions!$C$28,-$B$12,0) -> -33.047584 | G18: =E18+F18 -> 8.0309273 | H18: =IF(F18<0,E18/-F18,"") -> 1.243011 | I18: =$B$7*(1-Assumptions!$C$15)^(A18-1) -> 203.38666 | J18: =I18*Assumptions!$C$18/10 -> 52.880531 | K18: =-$B$9*(1+Assumptions!$C$24)^(A18-1) -> -4.738 | L18: =J18+K18 -> 48.142531 | M18: =IF(A18<=Assumptions!$C$28,-$B$13,0) -> -36.689428 | N18: =L18+M18 -> 11.453102 | O18: =IF(M18<0,L18/-M18,"") -> 1.3121636 | P18: =1/(1+Assumptions!$C$25)^A18 -> 0.84167999
A19: 3 | B19: =$B$6*(1-Assumptions!$C$15)^(A19-1) -> 172.97123 | C19: =B19*Assumptions!$C$18/10 -> 44.972519 | D19: =-$B$8*(1+Assumptions!$C$24)^(A19-1) -> -4.2436 | E19: =C19+D19 -> 40.728919 | F19: =IF(A19<=Assumptions!$C$28,-$B$12,0) -> -33.047584 | G19: =E19+F19 -> 7.6813348 | H19: =IF(F19<0,E19/-F19,"") -> 1.2324326 | I19: =$B$7*(1-Assumptions!$C$15)^(A19-1) -> 202.36972 | J19: =I19*Assumptions!$C$18/10 -> 52.616128 | K19: =-$B$9*(1+Assumptions!$C$24)^(A19-1) -> -4.88014 | L19: =J19+K19 -> 47.735988 | M19: =IF(A19<=Assumptions!$C$28,-$B$13,0) -> -36.689428 | N19: =L19+M19 -> 11.04656 | O19: =IF(M19<0,L19/-M19,"") -> 1.3010829 | P19: =1/(1+Assumptions!$C$25)^A19 -> 0.77218348
A20: 4 | B20: =$B$6*(1-Assumptions!$C$15)^(A20-1) -> 172.10637 | C20: =B20*Assumptions!$C$18/10 -> 44.747657 | D20: =-$B$8*(1+Assumptions!$C$24)^(A20-1) -> -4.370908 | E20: =C20+D20 -> 40.376749 | F20: =IF(A20<=Assumptions!$C$28,-$B$12,0) -> -33.047584 | G20: =E20+F20 -> 7.3291642 | H20: =IF(F20<0,E20/-F20,"") -> 1.2217761 | I20: =$B$7*(1-Assumptions!$C$15)^(A20-1) -> 201.35787 | J20: =I20*Assumptions!$C$18/10 -> 52.353047 | K20: =-$B$9*(1+Assumptions!$C$24)^(A20-1) -> -5.0265442 | L20: =J20+K20 -> 47.326503 | M20: =IF(A20<=Assumptions!$C$28,-$B$13,0) -> -36.689428 | N20: =L20+M20 -> 10.637075 | O20: =IF(M20<0,L20/-M20,"") -> 1.2899221 | P20: =1/(1+Assumptions!$C$25)^A20 -> 0.70842521
A21: 5 | B21: =$B$6*(1-Assumptions!$C$15)^(A21-1) -> 171.24584 | C21: =B21*Assumptions!$C$18/10 -> 44.523918 | D21: =-$B$8*(1+Assumptions!$C$24)^(A21-1) -> -4.5020352 | E21: =C21+D21 -> 40.021883 | F21: =IF(A21<=Assumptions!$C$28,-$B$12,0) -> -33.047584 | G21: =E21+F21 -> 6.9742987 | H21: =IF(F21<0,E21/-F21,"") -> 1.2110381 | I21: =$B$7*(1-Assumptions!$C$15)^(A21-1) -> 200.35109 | J21: =I21*Assumptions!$C$18/10 -> 52.091282 | K21: =-$B$9*(1+Assumptions!$C$24)^(A21-1) -> -5.1773405 | L21: =J21+K21 -> 46.913942 | M21: =IF(A21<=Assumptions!$C$28,-$B$13,0) -> -36.689428 | N21: =L21+M21 -> 10.224513 | O21: =IF(M21<0,L21/-M21,"") -> 1.2786774 | P21: =1/(1+Assumptions!$C$25)^A21 -> 0.64993139
A22: 6 | B22: =$B$6*(1-Assumptions!$C$15)^(A22-1) -> 170.38961 | C22: =B22*Assumptions!$C$18/10 -> 44.301299 | D22: =-$B$8*(1+Assumptions!$C$24)^(A22-1) -> -4.6370963 | E22: =C22+D22 -> 39.664202 | F22: =IF(A22<=Assumptions!$C$28,-$B$12,0) -> -33.047584 | G22: =E22+F22 -> 6.616618 | H22: =IF(F22<0,E22/-F22,"") -> 1.2002149 | I22: =$B$7*(1-Assumptions!$C$15)^(A22-1) -> 199.34933 | J22: =I22*Assumptions!$C$18/10 -> 51.830826 | K22: =-$B$9*(1+Assumptions!$C$24)^(A22-1) -> -5.3326607 | L22: =J22+K22 -> 46.498165 | M22: =IF(A22<=Assumptions!$C$28,-$B$13,0) -> -36.689428 | N22: =L22+M22 -> 9.8087367 | O22: =IF(M22<0,L22/-M22,"") -> 1.267345 | P22: =1/(1+Assumptions!$C$25)^A22 -> 0.59626733
A23: 7 | B23: =$B$6*(1-Assumptions!$C$15)^(A23-1) -> 169.53766 | C23: =B23*Assumptions!$C$18/10 -> 44.079792 | D23: =-$B$8*(1+Assumptions!$C$24)^(A23-1) -> -4.7762092 | E23: =C23+D23 -> 39.303583 | F23: =IF(A23<=Assumptions!$C$28,-$B$12,0) -> -33.047584 | G23: =E23+F23 -> 6.2559986 | H23: =IF(F23<0,E23/-F23,"") -> 1.1893027 | I23: =$B$7*(1-Assumptions!$C$15)^(A23-1) -> 198.35258 | J23: =I23*Assumptions!$C$18/10 -> 51.571672 | K23: =-$B$9*(1+Assumptions!$C$24)^(A23-1) -> -5.4926406 | L23: =J23+K23 -> 46.079031 | M23: =IF(A23<=Assumptions!$C$28,-$B$13,0) -> -36.689428 | N23: =L23+M23 -> 9.3896028 | O23: =IF(M23<0,L23/-M23,"") -> 1.2559212 | P23: =1/(1+Assumptions!$C$25)^A23 -> 0.54703424
A24: 8 | B24: =$B$6*(1-Assumptions!$C$15)^(A24-1) -> 168.68997 | C24: =B24*Assumptions!$C$18/10 -> 43.859393 | D24: =-$B$8*(1+Assumptions!$C$24)^(A24-1) -> -4.9194955 | E24: =C24+D24 -> 38.939898 | F24: =IF(A24<=Assumptions!$C$28,-$B$12,0) -> -33.047584 | G24: =E24+F24 -> 5.8923134 | H24: =IF(F24<0,E24/-F24,"") -> 1.1782979 | I24: =$B$7*(1-Assumptions!$C$15)^(A24-1) -> 197.36082 | J24: =I24*Assumptions!$C$18/10 -> 51.313813 | K24: =-$B$9*(1+Assumptions!$C$24)^(A24-1) -> -5.6574198 | L24: =J24+K24 -> 45.656393 | M24: =IF(A24<=Assumptions!$C$28,-$B$13,0) -> -36.689428 | N24: =L24+M24 -> 8.9669652 | O24: =IF(M24<0,L24/-M24,"") -> 1.2444019 | P24: =1/(1+Assumptions!$C$25)^A24 -> 0.50186628
A25: 9 | B25: =$B$6*(1-Assumptions!$C$15)^(A25-1) -> 167.84652 | C25: =B25*Assumptions!$C$18/10 -> 43.640096 | D25: =-$B$8*(1+Assumptions!$C$24)^(A25-1) -> -5.0670803 | E25: =C25+D25 -> 38.573016 | F25: =IF(A25<=Assumptions!$C$28,-$B$12,0) -> -33.047584 | G25: =E25+F25 -> 5.5254316 | H25: =IF(F25<0,E25/-F25,"") -> 1.1671962 | I25: =$B$7*(1-Assumptions!$C$15)^(A25-1) -> 196.37402 | J25: =I25*Assumptions!$C$18/10 -> 51.057244 | K25: =-$B$9*(1+Assumptions!$C$24)^(A25-1) -> -5.8271424 | L25: =J25+K25 -> 45.230102 | M25: =IF(A25<=Assumptions!$C$28,-$B$13,0) -> -36.689428 | N25: =L25+M25 -> 8.5406735 | O25: =IF(M25<0,L25/-M25,"") -> 1.232783 | P25: =1/(1+Assumptions!$C$25)^A25 -> 0.46042778
A26: 10 | B26: =$B$6*(1-Assumptions!$C$15)^(A26-1) -> 167.00729 | C26: =B26*Assumptions!$C$18/10 -> 43.421896 | D26: =-$B$8*(1+Assumptions!$C$24)^(A26-1) -> -5.2190927 | E26: =C26+D26 -> 38.202803 | F26: =IF(A26<=Assumptions!$C$28,-$B$12,0) -> -33.047584 | G26: =E26+F26 -> 5.1552187 | H26: =IF(F26<0,E26/-F26,"") -> 1.1559938 | I26: =$B$7*(1-Assumptions!$C$15)^(A26-1) -> 195.39215 | J26: =I26*Assumptions!$C$18/10 -> 50.801958 | K26: =-$B$9*(1+Assumptions!$C$24)^(A26-1) -> -6.0019566 | L26: =J26+K26 -> 44.800001 | M26: =IF(A26<=Assumptions!$C$28,-$B$13,0) -> -36.689428 | N26: =L26+M26 -> 8.110573 | O26: =IF(M26<0,L26/-M26,"") -> 1.2210602 | P26: =1/(1+Assumptions!$C$25)^A26 -> 0.42241081
A27: 11 | B27: =$B$6*(1-Assumptions!$C$15)^(A27-1) -> 166.17226 | C27: =B27*Assumptions!$C$18/10 -> 43.204786 | D27: =-$B$8*(1+Assumptions!$C$24)^(A27-1) -> -5.3756655 | E27: =C27+D27 -> 37.829121 | F27: =IF(A27<=Assumptions!$C$28,-$B$12,0) -> -33.047584 | G27: =E27+F27 -> 4.7815364 | H27: =IF(F27<0,E27/-F27,"") -> 1.1446864 | I27: =$B$7*(1-Assumptions!$C$15)^(A27-1) -> 194.41519 | J27: =I27*Assumptions!$C$18/10 -> 50.547948 | K27: =-$B$9*(1+Assumptions!$C$24)^(A27-1) -> -6.1820153 | L27: =J27+K27 -> 44.365933 | M27: =IF(A27<=Assumptions!$C$28,-$B$13,0) -> -36.689428 | N27: =L27+M27 -> 7.6765046 | O27: =IF(M27<0,L27/-M27,"") -> 1.2092293 | P27: =1/(1+Assumptions!$C$25)^A27 -> 0.38753285
A28: 12 | B28: =$B$6*(1-Assumptions!$C$15)^(A28-1) -> 165.34139 | C28: =B28*Assumptions!$C$18/10 -> 42.988762 | D28: =-$B$8*(1+Assumptions!$C$24)^(A28-1) -> -5.5369355 | E28: =C28+D28 -> 37.451827 | F28: =IF(A28<=Assumptions!$C$28,-$B$12,0) -> -33.047584 | G28: =E28+F28 -> 4.4042425 | H28: =IF(F28<0,E28/-F28,"") -> 1.1332697 | I28: =$B$7*(1-Assumptions!$C$15)^(A28-1) -> 193.44311 | J28: =I28*Assumptions!$C$18/10 -> 50.295208 | K28: =-$B$9*(1+Assumptions!$C$24)^(A28-1) -> -6.3674758 | L28: =J28+K28 -> 43.927733 | M28: =IF(A28<=Assumptions!$C$28,-$B$13,0) -> -36.689428 | N28: =L28+M28 -> 7.2383044 | O28: =IF(M28<0,L28/-M28,"") -> 1.1972858 | P28: =1/(1+Assumptions!$C$25)^A28 -> 0.35553473
... A41: 25 | B41: =$B$6*(1-Assumptions!$C$15)^(A41-1) -> 154.91078 | C41: =B41*Assumptions!$C$18/10 -> 40.276803 | D41: =-$B$8*(1+Assumptions!$C$24)^(A41-1) -> -8.1311764 | E41: =C41+D41 -> 32.145627 | F41: =IF(A41<=Assumptions!$C$28,-$B$12,0) -> 0 | G41: =E41+F41 -> 32.145627 | H41: =IF(F41<0,E41/-F41,"") | I41: =$B$7*(1-Assumptions!$C$15)^(A41-1) -> 181.23969 | J41: =I41*Assumptions!$C$18/10 -> 47.12232 | K41: =-$B$9*(1+Assumptions!$C$24)^(A41-1) -> -9.3508529 | L41: =J41+K41 -> 37.771467 | M41: =IF(A41<=Assumptions!$C$28,-$B$13,0) -> 0 | N41: =L41+M41 -> 37.771467 | O41: =IF(M41<0,L41/-M41,"") | P41: =1/(1+Assumptions!$C$25)^A41 -> 0.11596784
A44: Output | B44: Fixed-tilt | C44: Tracker | D44: Delta
A45: Project IRR (pre-tax) | B45: =IFERROR(IRR(E16:E41),0) -> 0.10050549 | C45: =IFERROR(IRR(L16:L41),0) -> 0.10812215 | D45: =C45-B45 -> 0.0076166596
A46: Equity IRR (pre-tax) | B46: =IFERROR(IRR(G16:G41),0) -> 0.11201779 | C46: =IFERROR(IRR(N16:N41),0) -> 0.13182595 | D46: =C46-B46 -> 0.019808157
A47: Project NPV @ WACC (INR cr) | B47: =E16+NPV(Assumptions!$C$25,E17:E41) -> 28.76473 | C47: =L16+NPV(Assumptions!$C$25,L17:L41) -> 55.577908 | D47: =C47-B47 -> 26.813178
A48: Minimum DSCR | B48: =MIN(H17:H41) -> 1.098319 | C48: =MIN(O17:O41) -> 1.1607331 | D48: =C48-B48 -> 0.06241406
A49: Average DSCR (debt years) | B49: =AVERAGE(H17:H41) -> 1.1773922 | C49: =AVERAGE(O17:O41) -> 1.2434694 | D49: =C49-B49 -> 0.066077155
A50: LCOE (INR/kWh) | B50: =(B4-SUMPRODUCT(D17:D41,P17:P41))/SUMPRODUCT(B17:B41,P17:P41)*10 -> 2.4257674 | C50: =(B5-SUMPRODUCT(K17:K41,P17:P41))/SUMPRODUCT(I17:I41,P17:P41)*10 -> 2.3122604 | D50: =C50-B50 -> -0.113507
A52: LCOE = (capex + PV of O&M) / PV of energy, at WACC. (INR crore / GWh) x 10 = INR/kWh.
